2025-07-14 11:20:54,707 - app.cache - INFO - ✅ Redis подключен успешно
2025-07-14 11:21:10,318 - app - ERROR - Unhandled exception on http://localhost:8000/api/categories/ | error_type=OperationalError
Traceback (most recent call last):
  File "/Users/olegkatrichuk/PycharmProjects/PythonAI/.venv/lib/python3.13/site-packages/sqlalchemy/engine/base.py", line 145, in __init__
    self._dbapi_connection = engine.raw_connection()
                             ~~~~~~~~~~~~~~~~~~~~~^^
  File "/Users/olegkatrichuk/PycharmProjects/PythonAI/.venv/lib/python3.13/site-packages/sqlalchemy/engine/base.py", line 3297, in raw_connection
    return self.pool.connect()
           ~~~~~~~~~~~~~~~~~^^
  File "/Users/olegkatrichuk/PycharmProjects/PythonAI/.venv/lib/python3.13/site-packages/sqlalchemy/pool/base.py", line 449, in connect
    return _ConnectionFairy._checkout(self)
           ~~~~~~~~~~~~~~~~~~~~~~~~~~^^^^^^
  File "/Users/olegkatrichuk/PycharmProjects/PythonAI/.venv/lib/python3.13/site-packages/sqlalchemy/pool/base.py", line 1264, in _checkout
    fairy = _ConnectionRecord.checkout(pool)
  File "/Users/olegkatrichuk/PycharmProjects/PythonAI/.venv/lib/python3.13/site-packages/sqlalchemy/pool/base.py", line 713, in checkout
    rec = pool._do_get()
  File "/Users/olegkatrichuk/PycharmProjects/PythonAI/.venv/lib/python3.13/site-packages/sqlalchemy/pool/impl.py", line 179, in _do_get
    with util.safe_reraise():
         ~~~~~~~~~~~~~~~~~^^
  File "/Users/olegkatrichuk/PycharmProjects/PythonAI/.venv/lib/python3.13/site-packages/sqlalchemy/util/langhelpers.py", line 224, in __exit__
    raise exc_value.with_traceback(exc_tb)
  File "/Users/olegkatrichuk/PycharmProjects/PythonAI/.venv/lib/python3.13/site-packages/sqlalchemy/pool/impl.py", line 177, in _do_get
    return self._create_connection()
           ~~~~~~~~~~~~~~~~~~~~~~~^^
  File "/Users/olegkatrichuk/PycharmProjects/PythonAI/.venv/lib/python3.13/site-packages/sqlalchemy/pool/base.py", line 390, in _create_connection
    return _ConnectionRecord(self)
  File "/Users/olegkatrichuk/PycharmProjects/PythonAI/.venv/lib/python3.13/site-packages/sqlalchemy/pool/base.py", line 675, in __init__
    self.__connect()
    ~~~~~~~~~~~~~~^^
  File "/Users/olegkatrichuk/PycharmProjects/PythonAI/.venv/lib/python3.13/site-packages/sqlalchemy/pool/base.py", line 901, in __connect
    with util.safe_reraise():
         ~~~~~~~~~~~~~~~~~^^
  File "/Users/olegkatrichuk/PycharmProjects/PythonAI/.venv/lib/python3.13/site-packages/sqlalchemy/util/langhelpers.py", line 224, in __exit__
    raise exc_value.with_traceback(exc_tb)
  File "/Users/olegkatrichuk/PycharmProjects/PythonAI/.venv/lib/python3.13/site-packages/sqlalchemy/pool/base.py", line 897, in __connect
    self.dbapi_connection = connection = pool._invoke_creator(self)
                                         ~~~~~~~~~~~~~~~~~~~~^^^^^^
  File "/Users/olegkatrichuk/PycharmProjects/PythonAI/.venv/lib/python3.13/site-packages/sqlalchemy/engine/create.py", line 646, in connect
    return dialect.connect(*cargs, **cparams)
           ~~~~~~~~~~~~~~~^^^^^^^^^^^^^^^^^^^
  File "/Users/olegkatrichuk/PycharmProjects/PythonAI/.venv/lib/python3.13/site-packages/sqlalchemy/engine/default.py", line 625, in connect
    return self.loaded_dbapi.connect(*cargs, **cparams)  # type: ignore[no-any-return]  # NOQA: E501
           ~~~~~~~~~~~~~~~~~~~~~~~~~^^^^^^^^^^^^^^^^^^^
  File "/Users/olegkatrichuk/PycharmProjects/PythonAI/.venv/lib/python3.13/site-packages/psycopg2/__init__.py", line 122, in connect
    conn = _connect(dsn, connection_factory=connection_factory, **kwasync)
psycopg2.OperationalError: connection to server at "localhost" (::1), port 5432 failed: Connection refused
	Is the server running on that host and accepting TCP/IP connections?
connection to server at "localhost" (127.0.0.1), port 5432 failed: Connection refused
	Is the server running on that host and accepting TCP/IP connections?


The above exception was the direct cause of the following exception:

Traceback (most recent call last):
  File "/Users/olegkatrichuk/PycharmProjects/PythonAI/.venv/lib/python3.13/site-packages/starlette/middleware/errors.py", line 165, in __call__
    await self.app(scope, receive, _send)
  File "/Users/olegkatrichuk/PycharmProjects/PythonAI/app/rate_limit.py", line 112, in __call__
    await self.app(scope, receive, send_wrapper)
  File "/Users/olegkatrichuk/PycharmProjects/PythonAI/.venv/lib/python3.13/site-packages/starlette/middleware/cors.py", line 85, in __call__
    await self.app(scope, receive, send)
  File "/Users/olegkatrichuk/PycharmProjects/PythonAI/.venv/lib/python3.13/site-packages/starlette/middleware/exceptions.py", line 62, in __call__
    await wrap_app_handling_exceptions(self.app, conn)(scope, receive, send)
  File "/Users/olegkatrichuk/PycharmProjects/PythonAI/.venv/lib/python3.13/site-packages/starlette/_exception_handler.py", line 53, in wrapped_app
    raise exc
  File "/Users/olegkatrichuk/PycharmProjects/PythonAI/.venv/lib/python3.13/site-packages/starlette/_exception_handler.py", line 42, in wrapped_app
    await app(scope, receive, sender)
  File "/Users/olegkatrichuk/PycharmProjects/PythonAI/.venv/lib/python3.13/site-packages/starlette/routing.py", line 714, in __call__
    await self.middleware_stack(scope, receive, send)
  File "/Users/olegkatrichuk/PycharmProjects/PythonAI/.venv/lib/python3.13/site-packages/starlette/routing.py", line 734, in app
    await route.handle(scope, receive, send)
  File "/Users/olegkatrichuk/PycharmProjects/PythonAI/.venv/lib/python3.13/site-packages/starlette/routing.py", line 288, in handle
    await self.app(scope, receive, send)
  File "/Users/olegkatrichuk/PycharmProjects/PythonAI/.venv/lib/python3.13/site-packages/starlette/routing.py", line 76, in app
    await wrap_app_handling_exceptions(app, request)(scope, receive, send)
  File "/Users/olegkatrichuk/PycharmProjects/PythonAI/.venv/lib/python3.13/site-packages/starlette/_exception_handler.py", line 53, in wrapped_app
    raise exc
  File "/Users/olegkatrichuk/PycharmProjects/PythonAI/.venv/lib/python3.13/site-packages/starlette/_exception_handler.py", line 42, in wrapped_app
    await app(scope, receive, sender)
  File "/Users/olegkatrichuk/PycharmProjects/PythonAI/.venv/lib/python3.13/site-packages/starlette/routing.py", line 73, in app
    response = await f(request)
               ^^^^^^^^^^^^^^^^
  File "/Users/olegkatrichuk/PycharmProjects/PythonAI/.venv/lib/python3.13/site-packages/fastapi/routing.py", line 301, in app
    raw_response = await run_endpoint_function(
                   ^^^^^^^^^^^^^^^^^^^^^^^^^^^^
    ...<3 lines>...
    )
    ^
  File "/Users/olegkatrichuk/PycharmProjects/PythonAI/.venv/lib/python3.13/site-packages/fastapi/routing.py", line 212, in run_endpoint_function
    return await dependant.call(**values)
           ^^^^^^^^^^^^^^^^^^^^^^^^^^^^^^
  File "/Users/olegkatrichuk/PycharmProjects/PythonAI/.venv/lib/python3.13/site-packages/slowapi/extension.py", line 734, in async_wrapper
    response = await func(*args, **kwargs)  # type: ignore
               ^^^^^^^^^^^^^^^^^^^^^^^^^^^
  File "/Users/olegkatrichuk/PycharmProjects/PythonAI/app/main.py", line 214, in read_categories
    return await crud.get_categories_with_cache(db, lang=lang)
           ^^^^^^^^^^^^^^^^^^^^^^^^^^^^^^^^^^^^^^^^^^^^^^^^^^^
  File "/Users/olegkatrichuk/PycharmProjects/PythonAI/app/crud.py", line 134, in get_categories_with_cache
    result = get_categories_with_translation(db, lang)
  File "/Users/olegkatrichuk/PycharmProjects/PythonAI/app/crud.py", line 107, in get_categories_with_translation
    ).all()
      ~~~^^
  File "/Users/olegkatrichuk/PycharmProjects/PythonAI/.venv/lib/python3.13/site-packages/sqlalchemy/orm/query.py", line 2704, in all
    return self._iter().all()  # type: ignore
           ~~~~~~~~~~^^
  File "/Users/olegkatrichuk/PycharmProjects/PythonAI/.venv/lib/python3.13/site-packages/sqlalchemy/orm/query.py", line 2857, in _iter
    result: Union[ScalarResult[_T], Result[_T]] = self.session.execute(
                                                  ~~~~~~~~~~~~~~~~~~~~^
        statement,
        ^^^^^^^^^^
        params,
        ^^^^^^^
        execution_options={"_sa_orm_load_options": self.load_options},
        ^^^^^^^^^^^^^^^^^^^^^^^^^^^^^^^^^^^^^^^^^^^^^^^^^^^^^^^^^^^^^^
    )
    ^
  File "/Users/olegkatrichuk/PycharmProjects/PythonAI/.venv/lib/python3.13/site-packages/sqlalchemy/orm/session.py", line 2365, in execute
    return self._execute_internal(
           ~~~~~~~~~~~~~~~~~~~~~~^
        statement,
        ^^^^^^^^^^
    ...<4 lines>...
        _add_event=_add_event,
        ^^^^^^^^^^^^^^^^^^^^^^
    )
    ^
  File "/Users/olegkatrichuk/PycharmProjects/PythonAI/.venv/lib/python3.13/site-packages/sqlalchemy/orm/session.py", line 2241, in _execute_internal
    conn = self._connection_for_bind(bind)
  File "/Users/olegkatrichuk/PycharmProjects/PythonAI/.venv/lib/python3.13/site-packages/sqlalchemy/orm/session.py", line 2110, in _connection_for_bind
    return trans._connection_for_bind(engine, execution_options)
           ~~~~~~~~~~~~~~~~~~~~~~~~~~^^^^^^^^^^^^^^^^^^^^^^^^^^^
  File "<string>", line 2, in _connection_for_bind
  File "/Users/olegkatrichuk/PycharmProjects/PythonAI/.venv/lib/python3.13/site-packages/sqlalchemy/orm/state_changes.py", line 139, in _go
    ret_value = fn(self, *arg, **kw)
  File "/Users/olegkatrichuk/PycharmProjects/PythonAI/.venv/lib/python3.13/site-packages/sqlalchemy/orm/session.py", line 1189, in _connection_for_bind
    conn = bind.connect()
  File "/Users/olegkatrichuk/PycharmProjects/PythonAI/.venv/lib/python3.13/site-packages/sqlalchemy/engine/base.py", line 3273, in connect
    return self._connection_cls(self)
           ~~~~~~~~~~~~~~~~~~~~^^^^^^
  File "/Users/olegkatrichuk/PycharmProjects/PythonAI/.venv/lib/python3.13/site-packages/sqlalchemy/engine/base.py", line 147, in __init__
    Connection._handle_dbapi_exception_noconnection(
    ~~~~~~~~~~~~~~~~~~~~~~~~~~~~~~~~~~~~~~~~~~~~~~~^
        err, dialect, engine
        ^^^^^^^^^^^^^^^^^^^^
    )
    ^
  File "/Users/olegkatrichuk/PycharmProjects/PythonAI/.venv/lib/python3.13/site-packages/sqlalchemy/engine/base.py", line 2436, in _handle_dbapi_exception_noconnection
    raise sqlalchemy_exception.with_traceback(exc_info[2]) from e
  File "/Users/olegkatrichuk/PycharmProjects/PythonAI/.venv/lib/python3.13/site-packages/sqlalchemy/engine/base.py", line 145, in __init__
    self._dbapi_connection = engine.raw_connection()
                             ~~~~~~~~~~~~~~~~~~~~~^^
  File "/Users/olegkatrichuk/PycharmProjects/PythonAI/.venv/lib/python3.13/site-packages/sqlalchemy/engine/base.py", line 3297, in raw_connection
    return self.pool.connect()
           ~~~~~~~~~~~~~~~~~^^
  File "/Users/olegkatrichuk/PycharmProjects/PythonAI/.venv/lib/python3.13/site-packages/sqlalchemy/pool/base.py", line 449, in connect
    return _ConnectionFairy._checkout(self)
           ~~~~~~~~~~~~~~~~~~~~~~~~~~^^^^^^
  File "/Users/olegkatrichuk/PycharmProjects/PythonAI/.venv/lib/python3.13/site-packages/sqlalchemy/pool/base.py", line 1264, in _checkout
    fairy = _ConnectionRecord.checkout(pool)
  File "/Users/olegkatrichuk/PycharmProjects/PythonAI/.venv/lib/python3.13/site-packages/sqlalchemy/pool/base.py", line 713, in checkout
    rec = pool._do_get()
  File "/Users/olegkatrichuk/PycharmProjects/PythonAI/.venv/lib/python3.13/site-packages/sqlalchemy/pool/impl.py", line 179, in _do_get
    with util.safe_reraise():
         ~~~~~~~~~~~~~~~~~^^
  File "/Users/olegkatrichuk/PycharmProjects/PythonAI/.venv/lib/python3.13/site-packages/sqlalchemy/util/langhelpers.py", line 224, in __exit__
    raise exc_value.with_traceback(exc_tb)
  File "/Users/olegkatrichuk/PycharmProjects/PythonAI/.venv/lib/python3.13/site-packages/sqlalchemy/pool/impl.py", line 177, in _do_get
    return self._create_connection()
           ~~~~~~~~~~~~~~~~~~~~~~~^^
  File "/Users/olegkatrichuk/PycharmProjects/PythonAI/.venv/lib/python3.13/site-packages/sqlalchemy/pool/base.py", line 390, in _create_connection
    return _ConnectionRecord(self)
  File "/Users/olegkatrichuk/PycharmProjects/PythonAI/.venv/lib/python3.13/site-packages/sqlalchemy/pool/base.py", line 675, in __init__
    self.__connect()
    ~~~~~~~~~~~~~~^^
  File "/Users/olegkatrichuk/PycharmProjects/PythonAI/.venv/lib/python3.13/site-packages/sqlalchemy/pool/base.py", line 901, in __connect
    with util.safe_reraise():
         ~~~~~~~~~~~~~~~~~^^
  File "/Users/olegkatrichuk/PycharmProjects/PythonAI/.venv/lib/python3.13/site-packages/sqlalchemy/util/langhelpers.py", line 224, in __exit__
    raise exc_value.with_traceback(exc_tb)
  File "/Users/olegkatrichuk/PycharmProjects/PythonAI/.venv/lib/python3.13/site-packages/sqlalchemy/pool/base.py", line 897, in __connect
    self.dbapi_connection = connection = pool._invoke_creator(self)
                                         ~~~~~~~~~~~~~~~~~~~~^^^^^^
  File "/Users/olegkatrichuk/PycharmProjects/PythonAI/.venv/lib/python3.13/site-packages/sqlalchemy/engine/create.py", line 646, in connect
    return dialect.connect(*cargs, **cparams)
           ~~~~~~~~~~~~~~~^^^^^^^^^^^^^^^^^^^
  File "/Users/olegkatrichuk/PycharmProjects/PythonAI/.venv/lib/python3.13/site-packages/sqlalchemy/engine/default.py", line 625, in connect
    return self.loaded_dbapi.connect(*cargs, **cparams)  # type: ignore[no-any-return]  # NOQA: E501
           ~~~~~~~~~~~~~~~~~~~~~~~~~^^^^^^^^^^^^^^^^^^^
  File "/Users/olegkatrichuk/PycharmProjects/PythonAI/.venv/lib/python3.13/site-packages/psycopg2/__init__.py", line 122, in connect
    conn = _connect(dsn, connection_factory=connection_factory, **kwasync)
sqlalchemy.exc.OperationalError: (psycopg2.OperationalError) connection to server at "localhost" (::1), port 5432 failed: Connection refused
	Is the server running on that host and accepting TCP/IP connections?
connection to server at "localhost" (127.0.0.1), port 5432 failed: Connection refused
	Is the server running on that host and accepting TCP/IP connections?

(Background on this error at: https://sqlalche.me/e/20/e3q8)
2025-07-14 11:21:10,339 - app - ERROR - Unhandled exception on http://localhost:8000/api/tools/featured | error_type=OperationalError
Traceback (most recent call last):
  File "/Users/olegkatrichuk/PycharmProjects/PythonAI/.venv/lib/python3.13/site-packages/sqlalchemy/engine/base.py", line 145, in __init__
    self._dbapi_connection = engine.raw_connection()
                             ~~~~~~~~~~~~~~~~~~~~~^^
  File "/Users/olegkatrichuk/PycharmProjects/PythonAI/.venv/lib/python3.13/site-packages/sqlalchemy/engine/base.py", line 3297, in raw_connection
    return self.pool.connect()
           ~~~~~~~~~~~~~~~~~^^
  File "/Users/olegkatrichuk/PycharmProjects/PythonAI/.venv/lib/python3.13/site-packages/sqlalchemy/pool/base.py", line 449, in connect
    return _ConnectionFairy._checkout(self)
           ~~~~~~~~~~~~~~~~~~~~~~~~~~^^^^^^
  File "/Users/olegkatrichuk/PycharmProjects/PythonAI/.venv/lib/python3.13/site-packages/sqlalchemy/pool/base.py", line 1264, in _checkout
    fairy = _ConnectionRecord.checkout(pool)
  File "/Users/olegkatrichuk/PycharmProjects/PythonAI/.venv/lib/python3.13/site-packages/sqlalchemy/pool/base.py", line 713, in checkout
    rec = pool._do_get()
  File "/Users/olegkatrichuk/PycharmProjects/PythonAI/.venv/lib/python3.13/site-packages/sqlalchemy/pool/impl.py", line 179, in _do_get
    with util.safe_reraise():
         ~~~~~~~~~~~~~~~~~^^
  File "/Users/olegkatrichuk/PycharmProjects/PythonAI/.venv/lib/python3.13/site-packages/sqlalchemy/util/langhelpers.py", line 224, in __exit__
    raise exc_value.with_traceback(exc_tb)
  File "/Users/olegkatrichuk/PycharmProjects/PythonAI/.venv/lib/python3.13/site-packages/sqlalchemy/pool/impl.py", line 177, in _do_get
    return self._create_connection()
           ~~~~~~~~~~~~~~~~~~~~~~~^^
  File "/Users/olegkatrichuk/PycharmProjects/PythonAI/.venv/lib/python3.13/site-packages/sqlalchemy/pool/base.py", line 390, in _create_connection
    return _ConnectionRecord(self)
  File "/Users/olegkatrichuk/PycharmProjects/PythonAI/.venv/lib/python3.13/site-packages/sqlalchemy/pool/base.py", line 675, in __init__
    self.__connect()
    ~~~~~~~~~~~~~~^^
  File "/Users/olegkatrichuk/PycharmProjects/PythonAI/.venv/lib/python3.13/site-packages/sqlalchemy/pool/base.py", line 901, in __connect
    with util.safe_reraise():
         ~~~~~~~~~~~~~~~~~^^
  File "/Users/olegkatrichuk/PycharmProjects/PythonAI/.venv/lib/python3.13/site-packages/sqlalchemy/util/langhelpers.py", line 224, in __exit__
    raise exc_value.with_traceback(exc_tb)
  File "/Users/olegkatrichuk/PycharmProjects/PythonAI/.venv/lib/python3.13/site-packages/sqlalchemy/pool/base.py", line 897, in __connect
    self.dbapi_connection = connection = pool._invoke_creator(self)
                                         ~~~~~~~~~~~~~~~~~~~~^^^^^^
  File "/Users/olegkatrichuk/PycharmProjects/PythonAI/.venv/lib/python3.13/site-packages/sqlalchemy/engine/create.py", line 646, in connect
    return dialect.connect(*cargs, **cparams)
           ~~~~~~~~~~~~~~~^^^^^^^^^^^^^^^^^^^
  File "/Users/olegkatrichuk/PycharmProjects/PythonAI/.venv/lib/python3.13/site-packages/sqlalchemy/engine/default.py", line 625, in connect
    return self.loaded_dbapi.connect(*cargs, **cparams)  # type: ignore[no-any-return]  # NOQA: E501
           ~~~~~~~~~~~~~~~~~~~~~~~~~^^^^^^^^^^^^^^^^^^^
  File "/Users/olegkatrichuk/PycharmProjects/PythonAI/.venv/lib/python3.13/site-packages/psycopg2/__init__.py", line 122, in connect
    conn = _connect(dsn, connection_factory=connection_factory, **kwasync)
psycopg2.OperationalError: connection to server at "localhost" (::1), port 5432 failed: Connection refused
	Is the server running on that host and accepting TCP/IP connections?
connection to server at "localhost" (127.0.0.1), port 5432 failed: Connection refused
	Is the server running on that host and accepting TCP/IP connections?


The above exception was the direct cause of the following exception:

Traceback (most recent call last):
  File "/Users/olegkatrichuk/PycharmProjects/PythonAI/.venv/lib/python3.13/site-packages/starlette/middleware/errors.py", line 165, in __call__
    await self.app(scope, receive, _send)
  File "/Users/olegkatrichuk/PycharmProjects/PythonAI/app/rate_limit.py", line 112, in __call__
    await self.app(scope, receive, send_wrapper)
  File "/Users/olegkatrichuk/PycharmProjects/PythonAI/.venv/lib/python3.13/site-packages/starlette/middleware/cors.py", line 85, in __call__
    await self.app(scope, receive, send)
  File "/Users/olegkatrichuk/PycharmProjects/PythonAI/.venv/lib/python3.13/site-packages/starlette/middleware/exceptions.py", line 62, in __call__
    await wrap_app_handling_exceptions(self.app, conn)(scope, receive, send)
  File "/Users/olegkatrichuk/PycharmProjects/PythonAI/.venv/lib/python3.13/site-packages/starlette/_exception_handler.py", line 53, in wrapped_app
    raise exc
  File "/Users/olegkatrichuk/PycharmProjects/PythonAI/.venv/lib/python3.13/site-packages/starlette/_exception_handler.py", line 42, in wrapped_app
    await app(scope, receive, sender)
  File "/Users/olegkatrichuk/PycharmProjects/PythonAI/.venv/lib/python3.13/site-packages/starlette/routing.py", line 714, in __call__
    await self.middleware_stack(scope, receive, send)
  File "/Users/olegkatrichuk/PycharmProjects/PythonAI/.venv/lib/python3.13/site-packages/starlette/routing.py", line 734, in app
    await route.handle(scope, receive, send)
  File "/Users/olegkatrichuk/PycharmProjects/PythonAI/.venv/lib/python3.13/site-packages/starlette/routing.py", line 288, in handle
    await self.app(scope, receive, send)
  File "/Users/olegkatrichuk/PycharmProjects/PythonAI/.venv/lib/python3.13/site-packages/starlette/routing.py", line 76, in app
    await wrap_app_handling_exceptions(app, request)(scope, receive, send)
  File "/Users/olegkatrichuk/PycharmProjects/PythonAI/.venv/lib/python3.13/site-packages/starlette/_exception_handler.py", line 53, in wrapped_app
    raise exc
  File "/Users/olegkatrichuk/PycharmProjects/PythonAI/.venv/lib/python3.13/site-packages/starlette/_exception_handler.py", line 42, in wrapped_app
    await app(scope, receive, sender)
  File "/Users/olegkatrichuk/PycharmProjects/PythonAI/.venv/lib/python3.13/site-packages/starlette/routing.py", line 73, in app
    response = await f(request)
               ^^^^^^^^^^^^^^^^
  File "/Users/olegkatrichuk/PycharmProjects/PythonAI/.venv/lib/python3.13/site-packages/fastapi/routing.py", line 301, in app
    raw_response = await run_endpoint_function(
                   ^^^^^^^^^^^^^^^^^^^^^^^^^^^^
    ...<3 lines>...
    )
    ^
  File "/Users/olegkatrichuk/PycharmProjects/PythonAI/.venv/lib/python3.13/site-packages/fastapi/routing.py", line 214, in run_endpoint_function
    return await run_in_threadpool(dependant.call, **values)
           ^^^^^^^^^^^^^^^^^^^^^^^^^^^^^^^^^^^^^^^^^^^^^^^^^
  File "/Users/olegkatrichuk/PycharmProjects/PythonAI/.venv/lib/python3.13/site-packages/starlette/concurrency.py", line 37, in run_in_threadpool
    return await anyio.to_thread.run_sync(func)
           ^^^^^^^^^^^^^^^^^^^^^^^^^^^^^^^^^^^^
  File "/Users/olegkatrichuk/PycharmProjects/PythonAI/.venv/lib/python3.13/site-packages/anyio/to_thread.py", line 56, in run_sync
    return await get_async_backend().run_sync_in_worker_thread(
           ^^^^^^^^^^^^^^^^^^^^^^^^^^^^^^^^^^^^^^^^^^^^^^^^^^^^
        func, args, abandon_on_cancel=abandon_on_cancel, limiter=limiter
        ^^^^^^^^^^^^^^^^^^^^^^^^^^^^^^^^^^^^^^^^^^^^^^^^^^^^^^^^^^^^^^^^
    )
    ^
  File "/Users/olegkatrichuk/PycharmProjects/PythonAI/.venv/lib/python3.13/site-packages/anyio/_backends/_asyncio.py", line 2470, in run_sync_in_worker_thread
    return await future
           ^^^^^^^^^^^^
  File "/Users/olegkatrichuk/PycharmProjects/PythonAI/.venv/lib/python3.13/site-packages/anyio/_backends/_asyncio.py", line 967, in run
    result = context.run(func, *args)
  File "/Users/olegkatrichuk/PycharmProjects/PythonAI/.venv/lib/python3.13/site-packages/slowapi/extension.py", line 766, in sync_wrapper
    response = func(*args, **kwargs)
  File "/Users/olegkatrichuk/PycharmProjects/PythonAI/app/main.py", line 262, in read_featured_tools
    tools_page = crud._get_featured_tools_cached(lang=lang, limit=6)
  File "/Users/olegkatrichuk/PycharmProjects/PythonAI/app/crud.py", line 197, in _get_featured_tools_cached
    ).limit(limit).all()
                   ~~~^^
  File "/Users/olegkatrichuk/PycharmProjects/PythonAI/.venv/lib/python3.13/site-packages/sqlalchemy/orm/query.py", line 2704, in all
    return self._iter().all()  # type: ignore
           ~~~~~~~~~~^^
  File "/Users/olegkatrichuk/PycharmProjects/PythonAI/.venv/lib/python3.13/site-packages/sqlalchemy/orm/query.py", line 2857, in _iter
    result: Union[ScalarResult[_T], Result[_T]] = self.session.execute(
                                                  ~~~~~~~~~~~~~~~~~~~~^
        statement,
        ^^^^^^^^^^
        params,
        ^^^^^^^
        execution_options={"_sa_orm_load_options": self.load_options},
        ^^^^^^^^^^^^^^^^^^^^^^^^^^^^^^^^^^^^^^^^^^^^^^^^^^^^^^^^^^^^^^
    )
    ^
  File "/Users/olegkatrichuk/PycharmProjects/PythonAI/.venv/lib/python3.13/site-packages/sqlalchemy/orm/session.py", line 2365, in execute
    return self._execute_internal(
           ~~~~~~~~~~~~~~~~~~~~~~^
        statement,
        ^^^^^^^^^^
    ...<4 lines>...
        _add_event=_add_event,
        ^^^^^^^^^^^^^^^^^^^^^^
    )
    ^
  File "/Users/olegkatrichuk/PycharmProjects/PythonAI/.venv/lib/python3.13/site-packages/sqlalchemy/orm/session.py", line 2241, in _execute_internal
    conn = self._connection_for_bind(bind)
  File "/Users/olegkatrichuk/PycharmProjects/PythonAI/.venv/lib/python3.13/site-packages/sqlalchemy/orm/session.py", line 2110, in _connection_for_bind
    return trans._connection_for_bind(engine, execution_options)
           ~~~~~~~~~~~~~~~~~~~~~~~~~~^^^^^^^^^^^^^^^^^^^^^^^^^^^
  File "<string>", line 2, in _connection_for_bind
  File "/Users/olegkatrichuk/PycharmProjects/PythonAI/.venv/lib/python3.13/site-packages/sqlalchemy/orm/state_changes.py", line 139, in _go
    ret_value = fn(self, *arg, **kw)
  File "/Users/olegkatrichuk/PycharmProjects/PythonAI/.venv/lib/python3.13/site-packages/sqlalchemy/orm/session.py", line 1189, in _connection_for_bind
    conn = bind.connect()
  File "/Users/olegkatrichuk/PycharmProjects/PythonAI/.venv/lib/python3.13/site-packages/sqlalchemy/engine/base.py", line 3273, in connect
    return self._connection_cls(self)
           ~~~~~~~~~~~~~~~~~~~~^^^^^^
  File "/Users/olegkatrichuk/PycharmProjects/PythonAI/.venv/lib/python3.13/site-packages/sqlalchemy/engine/base.py", line 147, in __init__
    Connection._handle_dbapi_exception_noconnection(
    ~~~~~~~~~~~~~~~~~~~~~~~~~~~~~~~~~~~~~~~~~~~~~~~^
        err, dialect, engine
        ^^^^^^^^^^^^^^^^^^^^
    )
    ^
  File "/Users/olegkatrichuk/PycharmProjects/PythonAI/.venv/lib/python3.13/site-packages/sqlalchemy/engine/base.py", line 2436, in _handle_dbapi_exception_noconnection
    raise sqlalchemy_exception.with_traceback(exc_info[2]) from e
  File "/Users/olegkatrichuk/PycharmProjects/PythonAI/.venv/lib/python3.13/site-packages/sqlalchemy/engine/base.py", line 145, in __init__
    self._dbapi_connection = engine.raw_connection()
                             ~~~~~~~~~~~~~~~~~~~~~^^
  File "/Users/olegkatrichuk/PycharmProjects/PythonAI/.venv/lib/python3.13/site-packages/sqlalchemy/engine/base.py", line 3297, in raw_connection
    return self.pool.connect()
           ~~~~~~~~~~~~~~~~~^^
  File "/Users/olegkatrichuk/PycharmProjects/PythonAI/.venv/lib/python3.13/site-packages/sqlalchemy/pool/base.py", line 449, in connect
    return _ConnectionFairy._checkout(self)
           ~~~~~~~~~~~~~~~~~~~~~~~~~~^^^^^^
  File "/Users/olegkatrichuk/PycharmProjects/PythonAI/.venv/lib/python3.13/site-packages/sqlalchemy/pool/base.py", line 1264, in _checkout
    fairy = _ConnectionRecord.checkout(pool)
  File "/Users/olegkatrichuk/PycharmProjects/PythonAI/.venv/lib/python3.13/site-packages/sqlalchemy/pool/base.py", line 713, in checkout
    rec = pool._do_get()
  File "/Users/olegkatrichuk/PycharmProjects/PythonAI/.venv/lib/python3.13/site-packages/sqlalchemy/pool/impl.py", line 179, in _do_get
    with util.safe_reraise():
         ~~~~~~~~~~~~~~~~~^^
  File "/Users/olegkatrichuk/PycharmProjects/PythonAI/.venv/lib/python3.13/site-packages/sqlalchemy/util/langhelpers.py", line 224, in __exit__
    raise exc_value.with_traceback(exc_tb)
  File "/Users/olegkatrichuk/PycharmProjects/PythonAI/.venv/lib/python3.13/site-packages/sqlalchemy/pool/impl.py", line 177, in _do_get
    return self._create_connection()
           ~~~~~~~~~~~~~~~~~~~~~~~^^
  File "/Users/olegkatrichuk/PycharmProjects/PythonAI/.venv/lib/python3.13/site-packages/sqlalchemy/pool/base.py", line 390, in _create_connection
    return _ConnectionRecord(self)
  File "/Users/olegkatrichuk/PycharmProjects/PythonAI/.venv/lib/python3.13/site-packages/sqlalchemy/pool/base.py", line 675, in __init__
    self.__connect()
    ~~~~~~~~~~~~~~^^
  File "/Users/olegkatrichuk/PycharmProjects/PythonAI/.venv/lib/python3.13/site-packages/sqlalchemy/pool/base.py", line 901, in __connect
    with util.safe_reraise():
         ~~~~~~~~~~~~~~~~~^^
  File "/Users/olegkatrichuk/PycharmProjects/PythonAI/.venv/lib/python3.13/site-packages/sqlalchemy/util/langhelpers.py", line 224, in __exit__
    raise exc_value.with_traceback(exc_tb)
  File "/Users/olegkatrichuk/PycharmProjects/PythonAI/.venv/lib/python3.13/site-packages/sqlalchemy/pool/base.py", line 897, in __connect
    self.dbapi_connection = connection = pool._invoke_creator(self)
                                         ~~~~~~~~~~~~~~~~~~~~^^^^^^
  File "/Users/olegkatrichuk/PycharmProjects/PythonAI/.venv/lib/python3.13/site-packages/sqlalchemy/engine/create.py", line 646, in connect
    return dialect.connect(*cargs, **cparams)
           ~~~~~~~~~~~~~~~^^^^^^^^^^^^^^^^^^^
  File "/Users/olegkatrichuk/PycharmProjects/PythonAI/.venv/lib/python3.13/site-packages/sqlalchemy/engine/default.py", line 625, in connect
    return self.loaded_dbapi.connect(*cargs, **cparams)  # type: ignore[no-any-return]  # NOQA: E501
           ~~~~~~~~~~~~~~~~~~~~~~~~~^^^^^^^^^^^^^^^^^^^
  File "/Users/olegkatrichuk/PycharmProjects/PythonAI/.venv/lib/python3.13/site-packages/psycopg2/__init__.py", line 122, in connect
    conn = _connect(dsn, connection_factory=connection_factory, **kwasync)
sqlalchemy.exc.OperationalError: (psycopg2.OperationalError) connection to server at "localhost" (::1), port 5432 failed: Connection refused
	Is the server running on that host and accepting TCP/IP connections?
connection to server at "localhost" (127.0.0.1), port 5432 failed: Connection refused
	Is the server running on that host and accepting TCP/IP connections?

(Background on this error at: https://sqlalche.me/e/20/e3q8)
2025-07-14 11:21:10,348 - app - ERROR - Unhandled exception on http://localhost:8000/api/tools/latest | error_type=OperationalError
Traceback (most recent call last):
  File "/Users/olegkatrichuk/PycharmProjects/PythonAI/.venv/lib/python3.13/site-packages/sqlalchemy/engine/base.py", line 145, in __init__
    self._dbapi_connection = engine.raw_connection()
                             ~~~~~~~~~~~~~~~~~~~~~^^
  File "/Users/olegkatrichuk/PycharmProjects/PythonAI/.venv/lib/python3.13/site-packages/sqlalchemy/engine/base.py", line 3297, in raw_connection
    return self.pool.connect()
           ~~~~~~~~~~~~~~~~~^^
  File "/Users/olegkatrichuk/PycharmProjects/PythonAI/.venv/lib/python3.13/site-packages/sqlalchemy/pool/base.py", line 449, in connect
    return _ConnectionFairy._checkout(self)
           ~~~~~~~~~~~~~~~~~~~~~~~~~~^^^^^^
  File "/Users/olegkatrichuk/PycharmProjects/PythonAI/.venv/lib/python3.13/site-packages/sqlalchemy/pool/base.py", line 1264, in _checkout
    fairy = _ConnectionRecord.checkout(pool)
  File "/Users/olegkatrichuk/PycharmProjects/PythonAI/.venv/lib/python3.13/site-packages/sqlalchemy/pool/base.py", line 713, in checkout
    rec = pool._do_get()
  File "/Users/olegkatrichuk/PycharmProjects/PythonAI/.venv/lib/python3.13/site-packages/sqlalchemy/pool/impl.py", line 179, in _do_get
    with util.safe_reraise():
         ~~~~~~~~~~~~~~~~~^^
  File "/Users/olegkatrichuk/PycharmProjects/PythonAI/.venv/lib/python3.13/site-packages/sqlalchemy/util/langhelpers.py", line 224, in __exit__
    raise exc_value.with_traceback(exc_tb)
  File "/Users/olegkatrichuk/PycharmProjects/PythonAI/.venv/lib/python3.13/site-packages/sqlalchemy/pool/impl.py", line 177, in _do_get
    return self._create_connection()
           ~~~~~~~~~~~~~~~~~~~~~~~^^
  File "/Users/olegkatrichuk/PycharmProjects/PythonAI/.venv/lib/python3.13/site-packages/sqlalchemy/pool/base.py", line 390, in _create_connection
    return _ConnectionRecord(self)
  File "/Users/olegkatrichuk/PycharmProjects/PythonAI/.venv/lib/python3.13/site-packages/sqlalchemy/pool/base.py", line 675, in __init__
    self.__connect()
    ~~~~~~~~~~~~~~^^
  File "/Users/olegkatrichuk/PycharmProjects/PythonAI/.venv/lib/python3.13/site-packages/sqlalchemy/pool/base.py", line 901, in __connect
    with util.safe_reraise():
         ~~~~~~~~~~~~~~~~~^^
  File "/Users/olegkatrichuk/PycharmProjects/PythonAI/.venv/lib/python3.13/site-packages/sqlalchemy/util/langhelpers.py", line 224, in __exit__
    raise exc_value.with_traceback(exc_tb)
  File "/Users/olegkatrichuk/PycharmProjects/PythonAI/.venv/lib/python3.13/site-packages/sqlalchemy/pool/base.py", line 897, in __connect
    self.dbapi_connection = connection = pool._invoke_creator(self)
                                         ~~~~~~~~~~~~~~~~~~~~^^^^^^
  File "/Users/olegkatrichuk/PycharmProjects/PythonAI/.venv/lib/python3.13/site-packages/sqlalchemy/engine/create.py", line 646, in connect
    return dialect.connect(*cargs, **cparams)
           ~~~~~~~~~~~~~~~^^^^^^^^^^^^^^^^^^^
  File "/Users/olegkatrichuk/PycharmProjects/PythonAI/.venv/lib/python3.13/site-packages/sqlalchemy/engine/default.py", line 625, in connect
    return self.loaded_dbapi.connect(*cargs, **cparams)  # type: ignore[no-any-return]  # NOQA: E501
           ~~~~~~~~~~~~~~~~~~~~~~~~~^^^^^^^^^^^^^^^^^^^
  File "/Users/olegkatrichuk/PycharmProjects/PythonAI/.venv/lib/python3.13/site-packages/psycopg2/__init__.py", line 122, in connect
    conn = _connect(dsn, connection_factory=connection_factory, **kwasync)
psycopg2.OperationalError: connection to server at "localhost" (::1), port 5432 failed: Connection refused
	Is the server running on that host and accepting TCP/IP connections?
connection to server at "localhost" (127.0.0.1), port 5432 failed: Connection refused
	Is the server running on that host and accepting TCP/IP connections?


The above exception was the direct cause of the following exception:

Traceback (most recent call last):
  File "/Users/olegkatrichuk/PycharmProjects/PythonAI/.venv/lib/python3.13/site-packages/starlette/middleware/errors.py", line 165, in __call__
    await self.app(scope, receive, _send)
  File "/Users/olegkatrichuk/PycharmProjects/PythonAI/app/rate_limit.py", line 112, in __call__
    await self.app(scope, receive, send_wrapper)
  File "/Users/olegkatrichuk/PycharmProjects/PythonAI/.venv/lib/python3.13/site-packages/starlette/middleware/cors.py", line 85, in __call__
    await self.app(scope, receive, send)
  File "/Users/olegkatrichuk/PycharmProjects/PythonAI/.venv/lib/python3.13/site-packages/starlette/middleware/exceptions.py", line 62, in __call__
    await wrap_app_handling_exceptions(self.app, conn)(scope, receive, send)
  File "/Users/olegkatrichuk/PycharmProjects/PythonAI/.venv/lib/python3.13/site-packages/starlette/_exception_handler.py", line 53, in wrapped_app
    raise exc
  File "/Users/olegkatrichuk/PycharmProjects/PythonAI/.venv/lib/python3.13/site-packages/starlette/_exception_handler.py", line 42, in wrapped_app
    await app(scope, receive, sender)
  File "/Users/olegkatrichuk/PycharmProjects/PythonAI/.venv/lib/python3.13/site-packages/starlette/routing.py", line 714, in __call__
    await self.middleware_stack(scope, receive, send)
  File "/Users/olegkatrichuk/PycharmProjects/PythonAI/.venv/lib/python3.13/site-packages/starlette/routing.py", line 734, in app
    await route.handle(scope, receive, send)
  File "/Users/olegkatrichuk/PycharmProjects/PythonAI/.venv/lib/python3.13/site-packages/starlette/routing.py", line 288, in handle
    await self.app(scope, receive, send)
  File "/Users/olegkatrichuk/PycharmProjects/PythonAI/.venv/lib/python3.13/site-packages/starlette/routing.py", line 76, in app
    await wrap_app_handling_exceptions(app, request)(scope, receive, send)
  File "/Users/olegkatrichuk/PycharmProjects/PythonAI/.venv/lib/python3.13/site-packages/starlette/_exception_handler.py", line 53, in wrapped_app
    raise exc
  File "/Users/olegkatrichuk/PycharmProjects/PythonAI/.venv/lib/python3.13/site-packages/starlette/_exception_handler.py", line 42, in wrapped_app
    await app(scope, receive, sender)
  File "/Users/olegkatrichuk/PycharmProjects/PythonAI/.venv/lib/python3.13/site-packages/starlette/routing.py", line 73, in app
    response = await f(request)
               ^^^^^^^^^^^^^^^^
  File "/Users/olegkatrichuk/PycharmProjects/PythonAI/.venv/lib/python3.13/site-packages/fastapi/routing.py", line 301, in app
    raw_response = await run_endpoint_function(
                   ^^^^^^^^^^^^^^^^^^^^^^^^^^^^
    ...<3 lines>...
    )
    ^
  File "/Users/olegkatrichuk/PycharmProjects/PythonAI/.venv/lib/python3.13/site-packages/fastapi/routing.py", line 214, in run_endpoint_function
    return await run_in_threadpool(dependant.call, **values)
           ^^^^^^^^^^^^^^^^^^^^^^^^^^^^^^^^^^^^^^^^^^^^^^^^^
  File "/Users/olegkatrichuk/PycharmProjects/PythonAI/.venv/lib/python3.13/site-packages/starlette/concurrency.py", line 37, in run_in_threadpool
    return await anyio.to_thread.run_sync(func)
           ^^^^^^^^^^^^^^^^^^^^^^^^^^^^^^^^^^^^
  File "/Users/olegkatrichuk/PycharmProjects/PythonAI/.venv/lib/python3.13/site-packages/anyio/to_thread.py", line 56, in run_sync
    return await get_async_backend().run_sync_in_worker_thread(
           ^^^^^^^^^^^^^^^^^^^^^^^^^^^^^^^^^^^^^^^^^^^^^^^^^^^^
        func, args, abandon_on_cancel=abandon_on_cancel, limiter=limiter
        ^^^^^^^^^^^^^^^^^^^^^^^^^^^^^^^^^^^^^^^^^^^^^^^^^^^^^^^^^^^^^^^^
    )
    ^
  File "/Users/olegkatrichuk/PycharmProjects/PythonAI/.venv/lib/python3.13/site-packages/anyio/_backends/_asyncio.py", line 2470, in run_sync_in_worker_thread
    return await future
           ^^^^^^^^^^^^
  File "/Users/olegkatrichuk/PycharmProjects/PythonAI/.venv/lib/python3.13/site-packages/anyio/_backends/_asyncio.py", line 967, in run
    result = context.run(func, *args)
  File "/Users/olegkatrichuk/PycharmProjects/PythonAI/.venv/lib/python3.13/site-packages/slowapi/extension.py", line 766, in sync_wrapper
    response = func(*args, **kwargs)
  File "/Users/olegkatrichuk/PycharmProjects/PythonAI/app/main.py", line 274, in read_latest_tools
    tools_page = crud._get_latest_tools_cached(lang=lang, limit=6)
  File "/Users/olegkatrichuk/PycharmProjects/PythonAI/app/crud.py", line 227, in _get_latest_tools_cached
    ).limit(limit).all()
                   ~~~^^
  File "/Users/olegkatrichuk/PycharmProjects/PythonAI/.venv/lib/python3.13/site-packages/sqlalchemy/orm/query.py", line 2704, in all
    return self._iter().all()  # type: ignore
           ~~~~~~~~~~^^
  File "/Users/olegkatrichuk/PycharmProjects/PythonAI/.venv/lib/python3.13/site-packages/sqlalchemy/orm/query.py", line 2857, in _iter
    result: Union[ScalarResult[_T], Result[_T]] = self.session.execute(
                                                  ~~~~~~~~~~~~~~~~~~~~^
        statement,
        ^^^^^^^^^^
        params,
        ^^^^^^^
        execution_options={"_sa_orm_load_options": self.load_options},
        ^^^^^^^^^^^^^^^^^^^^^^^^^^^^^^^^^^^^^^^^^^^^^^^^^^^^^^^^^^^^^^
    )
    ^
  File "/Users/olegkatrichuk/PycharmProjects/PythonAI/.venv/lib/python3.13/site-packages/sqlalchemy/orm/session.py", line 2365, in execute
    return self._execute_internal(
           ~~~~~~~~~~~~~~~~~~~~~~^
        statement,
        ^^^^^^^^^^
    ...<4 lines>...
        _add_event=_add_event,
        ^^^^^^^^^^^^^^^^^^^^^^
    )
    ^
  File "/Users/olegkatrichuk/PycharmProjects/PythonAI/.venv/lib/python3.13/site-packages/sqlalchemy/orm/session.py", line 2241, in _execute_internal
    conn = self._connection_for_bind(bind)
  File "/Users/olegkatrichuk/PycharmProjects/PythonAI/.venv/lib/python3.13/site-packages/sqlalchemy/orm/session.py", line 2110, in _connection_for_bind
    return trans._connection_for_bind(engine, execution_options)
           ~~~~~~~~~~~~~~~~~~~~~~~~~~^^^^^^^^^^^^^^^^^^^^^^^^^^^
  File "<string>", line 2, in _connection_for_bind
  File "/Users/olegkatrichuk/PycharmProjects/PythonAI/.venv/lib/python3.13/site-packages/sqlalchemy/orm/state_changes.py", line 139, in _go
    ret_value = fn(self, *arg, **kw)
  File "/Users/olegkatrichuk/PycharmProjects/PythonAI/.venv/lib/python3.13/site-packages/sqlalchemy/orm/session.py", line 1189, in _connection_for_bind
    conn = bind.connect()
  File "/Users/olegkatrichuk/PycharmProjects/PythonAI/.venv/lib/python3.13/site-packages/sqlalchemy/engine/base.py", line 3273, in connect
    return self._connection_cls(self)
           ~~~~~~~~~~~~~~~~~~~~^^^^^^
  File "/Users/olegkatrichuk/PycharmProjects/PythonAI/.venv/lib/python3.13/site-packages/sqlalchemy/engine/base.py", line 147, in __init__
    Connection._handle_dbapi_exception_noconnection(
    ~~~~~~~~~~~~~~~~~~~~~~~~~~~~~~~~~~~~~~~~~~~~~~~^
        err, dialect, engine
        ^^^^^^^^^^^^^^^^^^^^
    )
    ^
  File "/Users/olegkatrichuk/PycharmProjects/PythonAI/.venv/lib/python3.13/site-packages/sqlalchemy/engine/base.py", line 2436, in _handle_dbapi_exception_noconnection
    raise sqlalchemy_exception.with_traceback(exc_info[2]) from e
  File "/Users/olegkatrichuk/PycharmProjects/PythonAI/.venv/lib/python3.13/site-packages/sqlalchemy/engine/base.py", line 145, in __init__
    self._dbapi_connection = engine.raw_connection()
                             ~~~~~~~~~~~~~~~~~~~~~^^
  File "/Users/olegkatrichuk/PycharmProjects/PythonAI/.venv/lib/python3.13/site-packages/sqlalchemy/engine/base.py", line 3297, in raw_connection
    return self.pool.connect()
           ~~~~~~~~~~~~~~~~~^^
  File "/Users/olegkatrichuk/PycharmProjects/PythonAI/.venv/lib/python3.13/site-packages/sqlalchemy/pool/base.py", line 449, in connect
    return _ConnectionFairy._checkout(self)
           ~~~~~~~~~~~~~~~~~~~~~~~~~~^^^^^^
  File "/Users/olegkatrichuk/PycharmProjects/PythonAI/.venv/lib/python3.13/site-packages/sqlalchemy/pool/base.py", line 1264, in _checkout
    fairy = _ConnectionRecord.checkout(pool)
  File "/Users/olegkatrichuk/PycharmProjects/PythonAI/.venv/lib/python3.13/site-packages/sqlalchemy/pool/base.py", line 713, in checkout
    rec = pool._do_get()
  File "/Users/olegkatrichuk/PycharmProjects/PythonAI/.venv/lib/python3.13/site-packages/sqlalchemy/pool/impl.py", line 179, in _do_get
    with util.safe_reraise():
         ~~~~~~~~~~~~~~~~~^^
  File "/Users/olegkatrichuk/PycharmProjects/PythonAI/.venv/lib/python3.13/site-packages/sqlalchemy/util/langhelpers.py", line 224, in __exit__
    raise exc_value.with_traceback(exc_tb)
  File "/Users/olegkatrichuk/PycharmProjects/PythonAI/.venv/lib/python3.13/site-packages/sqlalchemy/pool/impl.py", line 177, in _do_get
    return self._create_connection()
           ~~~~~~~~~~~~~~~~~~~~~~~^^
  File "/Users/olegkatrichuk/PycharmProjects/PythonAI/.venv/lib/python3.13/site-packages/sqlalchemy/pool/base.py", line 390, in _create_connection
    return _ConnectionRecord(self)
  File "/Users/olegkatrichuk/PycharmProjects/PythonAI/.venv/lib/python3.13/site-packages/sqlalchemy/pool/base.py", line 675, in __init__
    self.__connect()
    ~~~~~~~~~~~~~~^^
  File "/Users/olegkatrichuk/PycharmProjects/PythonAI/.venv/lib/python3.13/site-packages/sqlalchemy/pool/base.py", line 901, in __connect
    with util.safe_reraise():
         ~~~~~~~~~~~~~~~~~^^
  File "/Users/olegkatrichuk/PycharmProjects/PythonAI/.venv/lib/python3.13/site-packages/sqlalchemy/util/langhelpers.py", line 224, in __exit__
    raise exc_value.with_traceback(exc_tb)
  File "/Users/olegkatrichuk/PycharmProjects/PythonAI/.venv/lib/python3.13/site-packages/sqlalchemy/pool/base.py", line 897, in __connect
    self.dbapi_connection = connection = pool._invoke_creator(self)
                                         ~~~~~~~~~~~~~~~~~~~~^^^^^^
  File "/Users/olegkatrichuk/PycharmProjects/PythonAI/.venv/lib/python3.13/site-packages/sqlalchemy/engine/create.py", line 646, in connect
    return dialect.connect(*cargs, **cparams)
           ~~~~~~~~~~~~~~~^^^^^^^^^^^^^^^^^^^
  File "/Users/olegkatrichuk/PycharmProjects/PythonAI/.venv/lib/python3.13/site-packages/sqlalchemy/engine/default.py", line 625, in connect
    return self.loaded_dbapi.connect(*cargs, **cparams)  # type: ignore[no-any-return]  # NOQA: E501
           ~~~~~~~~~~~~~~~~~~~~~~~~~^^^^^^^^^^^^^^^^^^^
  File "/Users/olegkatrichuk/PycharmProjects/PythonAI/.venv/lib/python3.13/site-packages/psycopg2/__init__.py", line 122, in connect
    conn = _connect(dsn, connection_factory=connection_factory, **kwasync)
sqlalchemy.exc.OperationalError: (psycopg2.OperationalError) connection to server at "localhost" (::1), port 5432 failed: Connection refused
	Is the server running on that host and accepting TCP/IP connections?
connection to server at "localhost" (127.0.0.1), port 5432 failed: Connection refused
	Is the server running on that host and accepting TCP/IP connections?

(Background on this error at: https://sqlalche.me/e/20/e3q8)
2025-07-14 11:21:12,327 - app - ERROR - Unhandled exception on http://localhost:8000/api/analytics/page-view | error_type=OperationalError
Traceback (most recent call last):
  File "/Users/olegkatrichuk/PycharmProjects/PythonAI/.venv/lib/python3.13/site-packages/sqlalchemy/engine/base.py", line 145, in __init__
    self._dbapi_connection = engine.raw_connection()
                             ~~~~~~~~~~~~~~~~~~~~~^^
  File "/Users/olegkatrichuk/PycharmProjects/PythonAI/.venv/lib/python3.13/site-packages/sqlalchemy/engine/base.py", line 3297, in raw_connection
    return self.pool.connect()
           ~~~~~~~~~~~~~~~~~^^
  File "/Users/olegkatrichuk/PycharmProjects/PythonAI/.venv/lib/python3.13/site-packages/sqlalchemy/pool/base.py", line 449, in connect
    return _ConnectionFairy._checkout(self)
           ~~~~~~~~~~~~~~~~~~~~~~~~~~^^^^^^
  File "/Users/olegkatrichuk/PycharmProjects/PythonAI/.venv/lib/python3.13/site-packages/sqlalchemy/pool/base.py", line 1264, in _checkout
    fairy = _ConnectionRecord.checkout(pool)
  File "/Users/olegkatrichuk/PycharmProjects/PythonAI/.venv/lib/python3.13/site-packages/sqlalchemy/pool/base.py", line 713, in checkout
    rec = pool._do_get()
  File "/Users/olegkatrichuk/PycharmProjects/PythonAI/.venv/lib/python3.13/site-packages/sqlalchemy/pool/impl.py", line 179, in _do_get
    with util.safe_reraise():
         ~~~~~~~~~~~~~~~~~^^
  File "/Users/olegkatrichuk/PycharmProjects/PythonAI/.venv/lib/python3.13/site-packages/sqlalchemy/util/langhelpers.py", line 224, in __exit__
    raise exc_value.with_traceback(exc_tb)
  File "/Users/olegkatrichuk/PycharmProjects/PythonAI/.venv/lib/python3.13/site-packages/sqlalchemy/pool/impl.py", line 177, in _do_get
    return self._create_connection()
           ~~~~~~~~~~~~~~~~~~~~~~~^^
  File "/Users/olegkatrichuk/PycharmProjects/PythonAI/.venv/lib/python3.13/site-packages/sqlalchemy/pool/base.py", line 390, in _create_connection
    return _ConnectionRecord(self)
  File "/Users/olegkatrichuk/PycharmProjects/PythonAI/.venv/lib/python3.13/site-packages/sqlalchemy/pool/base.py", line 675, in __init__
    self.__connect()
    ~~~~~~~~~~~~~~^^
  File "/Users/olegkatrichuk/PycharmProjects/PythonAI/.venv/lib/python3.13/site-packages/sqlalchemy/pool/base.py", line 901, in __connect
    with util.safe_reraise():
         ~~~~~~~~~~~~~~~~~^^
  File "/Users/olegkatrichuk/PycharmProjects/PythonAI/.venv/lib/python3.13/site-packages/sqlalchemy/util/langhelpers.py", line 224, in __exit__
    raise exc_value.with_traceback(exc_tb)
  File "/Users/olegkatrichuk/PycharmProjects/PythonAI/.venv/lib/python3.13/site-packages/sqlalchemy/pool/base.py", line 897, in __connect
    self.dbapi_connection = connection = pool._invoke_creator(self)
                                         ~~~~~~~~~~~~~~~~~~~~^^^^^^
  File "/Users/olegkatrichuk/PycharmProjects/PythonAI/.venv/lib/python3.13/site-packages/sqlalchemy/engine/create.py", line 646, in connect
    return dialect.connect(*cargs, **cparams)
           ~~~~~~~~~~~~~~~^^^^^^^^^^^^^^^^^^^
  File "/Users/olegkatrichuk/PycharmProjects/PythonAI/.venv/lib/python3.13/site-packages/sqlalchemy/engine/default.py", line 625, in connect
    return self.loaded_dbapi.connect(*cargs, **cparams)  # type: ignore[no-any-return]  # NOQA: E501
           ~~~~~~~~~~~~~~~~~~~~~~~~~^^^^^^^^^^^^^^^^^^^
  File "/Users/olegkatrichuk/PycharmProjects/PythonAI/.venv/lib/python3.13/site-packages/psycopg2/__init__.py", line 122, in connect
    conn = _connect(dsn, connection_factory=connection_factory, **kwasync)
psycopg2.OperationalError: connection to server at "localhost" (::1), port 5432 failed: Connection refused
	Is the server running on that host and accepting TCP/IP connections?
connection to server at "localhost" (127.0.0.1), port 5432 failed: Connection refused
	Is the server running on that host and accepting TCP/IP connections?


The above exception was the direct cause of the following exception:

Traceback (most recent call last):
  File "/Users/olegkatrichuk/PycharmProjects/PythonAI/.venv/lib/python3.13/site-packages/starlette/middleware/errors.py", line 165, in __call__
    await self.app(scope, receive, _send)
  File "/Users/olegkatrichuk/PycharmProjects/PythonAI/app/rate_limit.py", line 112, in __call__
    await self.app(scope, receive, send_wrapper)
  File "/Users/olegkatrichuk/PycharmProjects/PythonAI/.venv/lib/python3.13/site-packages/starlette/middleware/cors.py", line 93, in __call__
    await self.simple_response(scope, receive, send, request_headers=headers)
  File "/Users/olegkatrichuk/PycharmProjects/PythonAI/.venv/lib/python3.13/site-packages/starlette/middleware/cors.py", line 144, in simple_response
    await self.app(scope, receive, send)
  File "/Users/olegkatrichuk/PycharmProjects/PythonAI/.venv/lib/python3.13/site-packages/starlette/middleware/exceptions.py", line 62, in __call__
    await wrap_app_handling_exceptions(self.app, conn)(scope, receive, send)
  File "/Users/olegkatrichuk/PycharmProjects/PythonAI/.venv/lib/python3.13/site-packages/starlette/_exception_handler.py", line 53, in wrapped_app
    raise exc
  File "/Users/olegkatrichuk/PycharmProjects/PythonAI/.venv/lib/python3.13/site-packages/starlette/_exception_handler.py", line 42, in wrapped_app
    await app(scope, receive, sender)
  File "/Users/olegkatrichuk/PycharmProjects/PythonAI/.venv/lib/python3.13/site-packages/starlette/routing.py", line 714, in __call__
    await self.middleware_stack(scope, receive, send)
  File "/Users/olegkatrichuk/PycharmProjects/PythonAI/.venv/lib/python3.13/site-packages/starlette/routing.py", line 734, in app
    await route.handle(scope, receive, send)
  File "/Users/olegkatrichuk/PycharmProjects/PythonAI/.venv/lib/python3.13/site-packages/starlette/routing.py", line 288, in handle
    await self.app(scope, receive, send)
  File "/Users/olegkatrichuk/PycharmProjects/PythonAI/.venv/lib/python3.13/site-packages/starlette/routing.py", line 76, in app
    await wrap_app_handling_exceptions(app, request)(scope, receive, send)
  File "/Users/olegkatrichuk/PycharmProjects/PythonAI/.venv/lib/python3.13/site-packages/starlette/_exception_handler.py", line 53, in wrapped_app
    raise exc
  File "/Users/olegkatrichuk/PycharmProjects/PythonAI/.venv/lib/python3.13/site-packages/starlette/_exception_handler.py", line 42, in wrapped_app
    await app(scope, receive, sender)
  File "/Users/olegkatrichuk/PycharmProjects/PythonAI/.venv/lib/python3.13/site-packages/starlette/routing.py", line 73, in app
    response = await f(request)
               ^^^^^^^^^^^^^^^^
  File "/Users/olegkatrichuk/PycharmProjects/PythonAI/.venv/lib/python3.13/site-packages/fastapi/routing.py", line 301, in app
    raw_response = await run_endpoint_function(
                   ^^^^^^^^^^^^^^^^^^^^^^^^^^^^
    ...<3 lines>...
    )
    ^
  File "/Users/olegkatrichuk/PycharmProjects/PythonAI/.venv/lib/python3.13/site-packages/fastapi/routing.py", line 214, in run_endpoint_function
    return await run_in_threadpool(dependant.call, **values)
           ^^^^^^^^^^^^^^^^^^^^^^^^^^^^^^^^^^^^^^^^^^^^^^^^^
  File "/Users/olegkatrichuk/PycharmProjects/PythonAI/.venv/lib/python3.13/site-packages/starlette/concurrency.py", line 37, in run_in_threadpool
    return await anyio.to_thread.run_sync(func)
           ^^^^^^^^^^^^^^^^^^^^^^^^^^^^^^^^^^^^
  File "/Users/olegkatrichuk/PycharmProjects/PythonAI/.venv/lib/python3.13/site-packages/anyio/to_thread.py", line 56, in run_sync
    return await get_async_backend().run_sync_in_worker_thread(
           ^^^^^^^^^^^^^^^^^^^^^^^^^^^^^^^^^^^^^^^^^^^^^^^^^^^^
        func, args, abandon_on_cancel=abandon_on_cancel, limiter=limiter
        ^^^^^^^^^^^^^^^^^^^^^^^^^^^^^^^^^^^^^^^^^^^^^^^^^^^^^^^^^^^^^^^^
    )
    ^
  File "/Users/olegkatrichuk/PycharmProjects/PythonAI/.venv/lib/python3.13/site-packages/anyio/_backends/_asyncio.py", line 2470, in run_sync_in_worker_thread
    return await future
           ^^^^^^^^^^^^
  File "/Users/olegkatrichuk/PycharmProjects/PythonAI/.venv/lib/python3.13/site-packages/anyio/_backends/_asyncio.py", line 967, in run
    result = context.run(func, *args)
  File "/Users/olegkatrichuk/PycharmProjects/PythonAI/.venv/lib/python3.13/site-packages/slowapi/extension.py", line 766, in sync_wrapper
    response = func(*args, **kwargs)
  File "/Users/olegkatrichuk/PycharmProjects/PythonAI/app/main.py", line 370, in track_page_view
    return crud.create_page_view(db=db, page_view=page_view, user_id=user_id)
           ~~~~~~~~~~~~~~~~~~~~~^^^^^^^^^^^^^^^^^^^^^^^^^^^^^^^^^^^^^^^^^^^^^
  File "/Users/olegkatrichuk/PycharmProjects/PythonAI/app/crud.py", line 560, in create_page_view
    db.commit()
    ~~~~~~~~~^^
  File "/Users/olegkatrichuk/PycharmProjects/PythonAI/.venv/lib/python3.13/site-packages/sqlalchemy/orm/session.py", line 2032, in commit
    trans.commit(_to_root=True)
    ~~~~~~~~~~~~^^^^^^^^^^^^^^^
  File "<string>", line 2, in commit
  File "/Users/olegkatrichuk/PycharmProjects/PythonAI/.venv/lib/python3.13/site-packages/sqlalchemy/orm/state_changes.py", line 139, in _go
    ret_value = fn(self, *arg, **kw)
  File "/Users/olegkatrichuk/PycharmProjects/PythonAI/.venv/lib/python3.13/site-packages/sqlalchemy/orm/session.py", line 1313, in commit
    self._prepare_impl()
    ~~~~~~~~~~~~~~~~~~^^
  File "<string>", line 2, in _prepare_impl
  File "/Users/olegkatrichuk/PycharmProjects/PythonAI/.venv/lib/python3.13/site-packages/sqlalchemy/orm/state_changes.py", line 139, in _go
    ret_value = fn(self, *arg, **kw)
  File "/Users/olegkatrichuk/PycharmProjects/PythonAI/.venv/lib/python3.13/site-packages/sqlalchemy/orm/session.py", line 1288, in _prepare_impl
    self.session.flush()
    ~~~~~~~~~~~~~~~~~~^^
  File "/Users/olegkatrichuk/PycharmProjects/PythonAI/.venv/lib/python3.13/site-packages/sqlalchemy/orm/session.py", line 4345, in flush
    self._flush(objects)
    ~~~~~~~~~~~^^^^^^^^^
  File "/Users/olegkatrichuk/PycharmProjects/PythonAI/.venv/lib/python3.13/site-packages/sqlalchemy/orm/session.py", line 4480, in _flush
    with util.safe_reraise():
         ~~~~~~~~~~~~~~~~~^^
  File "/Users/olegkatrichuk/PycharmProjects/PythonAI/.venv/lib/python3.13/site-packages/sqlalchemy/util/langhelpers.py", line 224, in __exit__
    raise exc_value.with_traceback(exc_tb)
  File "/Users/olegkatrichuk/PycharmProjects/PythonAI/.venv/lib/python3.13/site-packages/sqlalchemy/orm/session.py", line 4441, in _flush
    flush_context.execute()
    ~~~~~~~~~~~~~~~~~~~~~^^
  File "/Users/olegkatrichuk/PycharmProjects/PythonAI/.venv/lib/python3.13/site-packages/sqlalchemy/orm/unitofwork.py", line 466, in execute
    rec.execute(self)
    ~~~~~~~~~~~^^^^^^
  File "/Users/olegkatrichuk/PycharmProjects/PythonAI/.venv/lib/python3.13/site-packages/sqlalchemy/orm/unitofwork.py", line 642, in execute
    util.preloaded.orm_persistence.save_obj(
    ~~~~~~~~~~~~~~~~~~~~~~~~~~~~~~~~~~~~~~~^
        self.mapper,
        ^^^^^^^^^^^^
        uow.states_for_mapper_hierarchy(self.mapper, False, False),
        ^^^^^^^^^^^^^^^^^^^^^^^^^^^^^^^^^^^^^^^^^^^^^^^^^^^^^^^^^^^
        uow,
        ^^^^
    )
    ^
  File "/Users/olegkatrichuk/PycharmProjects/PythonAI/.venv/lib/python3.13/site-packages/sqlalchemy/orm/persistence.py", line 68, in save_obj
    ) in _organize_states_for_save(base_mapper, states, uowtransaction):
         ~~~~~~~~~~~~~~~~~~~~~~~~~^^^^^^^^^^^^^^^^^^^^^^^^^^^^^^^^^^^^^
  File "/Users/olegkatrichuk/PycharmProjects/PythonAI/.venv/lib/python3.13/site-packages/sqlalchemy/orm/persistence.py", line 223, in _organize_states_for_save
    for state, dict_, mapper, connection in _connections_for_states(
                                            ~~~~~~~~~~~~~~~~~~~~~~~^
        base_mapper, uowtransaction, states
        ^^^^^^^^^^^^^^^^^^^^^^^^^^^^^^^^^^^
    ):
    ^
  File "/Users/olegkatrichuk/PycharmProjects/PythonAI/.venv/lib/python3.13/site-packages/sqlalchemy/orm/persistence.py", line 1753, in _connections_for_states
    connection = uowtransaction.transaction.connection(base_mapper)
  File "<string>", line 2, in connection
  File "/Users/olegkatrichuk/PycharmProjects/PythonAI/.venv/lib/python3.13/site-packages/sqlalchemy/orm/state_changes.py", line 139, in _go
    ret_value = fn(self, *arg, **kw)
  File "/Users/olegkatrichuk/PycharmProjects/PythonAI/.venv/lib/python3.13/site-packages/sqlalchemy/orm/session.py", line 1039, in connection
    return self._connection_for_bind(bind, execution_options)
           ~~~~~~~~~~~~~~~~~~~~~~~~~^^^^^^^^^^^^^^^^^^^^^^^^^
  File "<string>", line 2, in _connection_for_bind
  File "/Users/olegkatrichuk/PycharmProjects/PythonAI/.venv/lib/python3.13/site-packages/sqlalchemy/orm/state_changes.py", line 139, in _go
    ret_value = fn(self, *arg, **kw)
  File "/Users/olegkatrichuk/PycharmProjects/PythonAI/.venv/lib/python3.13/site-packages/sqlalchemy/orm/session.py", line 1175, in _connection_for_bind
    conn = self._parent._connection_for_bind(
        bind, execution_options
    )
  File "<string>", line 2, in _connection_for_bind
  File "/Users/olegkatrichuk/PycharmProjects/PythonAI/.venv/lib/python3.13/site-packages/sqlalchemy/orm/state_changes.py", line 139, in _go
    ret_value = fn(self, *arg, **kw)
  File "/Users/olegkatrichuk/PycharmProjects/PythonAI/.venv/lib/python3.13/site-packages/sqlalchemy/orm/session.py", line 1189, in _connection_for_bind
    conn = bind.connect()
  File "/Users/olegkatrichuk/PycharmProjects/PythonAI/.venv/lib/python3.13/site-packages/sqlalchemy/engine/base.py", line 3273, in connect
    return self._connection_cls(self)
           ~~~~~~~~~~~~~~~~~~~~^^^^^^
  File "/Users/olegkatrichuk/PycharmProjects/PythonAI/.venv/lib/python3.13/site-packages/sqlalchemy/engine/base.py", line 147, in __init__
    Connection._handle_dbapi_exception_noconnection(
    ~~~~~~~~~~~~~~~~~~~~~~~~~~~~~~~~~~~~~~~~~~~~~~~^
        err, dialect, engine
        ^^^^^^^^^^^^^^^^^^^^
    )
    ^
  File "/Users/olegkatrichuk/PycharmProjects/PythonAI/.venv/lib/python3.13/site-packages/sqlalchemy/engine/base.py", line 2436, in _handle_dbapi_exception_noconnection
    raise sqlalchemy_exception.with_traceback(exc_info[2]) from e
  File "/Users/olegkatrichuk/PycharmProjects/PythonAI/.venv/lib/python3.13/site-packages/sqlalchemy/engine/base.py", line 145, in __init__
    self._dbapi_connection = engine.raw_connection()
                             ~~~~~~~~~~~~~~~~~~~~~^^
  File "/Users/olegkatrichuk/PycharmProjects/PythonAI/.venv/lib/python3.13/site-packages/sqlalchemy/engine/base.py", line 3297, in raw_connection
    return self.pool.connect()
           ~~~~~~~~~~~~~~~~~^^
  File "/Users/olegkatrichuk/PycharmProjects/PythonAI/.venv/lib/python3.13/site-packages/sqlalchemy/pool/base.py", line 449, in connect
    return _ConnectionFairy._checkout(self)
           ~~~~~~~~~~~~~~~~~~~~~~~~~~^^^^^^
  File "/Users/olegkatrichuk/PycharmProjects/PythonAI/.venv/lib/python3.13/site-packages/sqlalchemy/pool/base.py", line 1264, in _checkout
    fairy = _ConnectionRecord.checkout(pool)
  File "/Users/olegkatrichuk/PycharmProjects/PythonAI/.venv/lib/python3.13/site-packages/sqlalchemy/pool/base.py", line 713, in checkout
    rec = pool._do_get()
  File "/Users/olegkatrichuk/PycharmProjects/PythonAI/.venv/lib/python3.13/site-packages/sqlalchemy/pool/impl.py", line 179, in _do_get
    with util.safe_reraise():
         ~~~~~~~~~~~~~~~~~^^
  File "/Users/olegkatrichuk/PycharmProjects/PythonAI/.venv/lib/python3.13/site-packages/sqlalchemy/util/langhelpers.py", line 224, in __exit__
    raise exc_value.with_traceback(exc_tb)
  File "/Users/olegkatrichuk/PycharmProjects/PythonAI/.venv/lib/python3.13/site-packages/sqlalchemy/pool/impl.py", line 177, in _do_get
    return self._create_connection()
           ~~~~~~~~~~~~~~~~~~~~~~~^^
  File "/Users/olegkatrichuk/PycharmProjects/PythonAI/.venv/lib/python3.13/site-packages/sqlalchemy/pool/base.py", line 390, in _create_connection
    return _ConnectionRecord(self)
  File "/Users/olegkatrichuk/PycharmProjects/PythonAI/.venv/lib/python3.13/site-packages/sqlalchemy/pool/base.py", line 675, in __init__
    self.__connect()
    ~~~~~~~~~~~~~~^^
  File "/Users/olegkatrichuk/PycharmProjects/PythonAI/.venv/lib/python3.13/site-packages/sqlalchemy/pool/base.py", line 901, in __connect
    with util.safe_reraise():
         ~~~~~~~~~~~~~~~~~^^
  File "/Users/olegkatrichuk/PycharmProjects/PythonAI/.venv/lib/python3.13/site-packages/sqlalchemy/util/langhelpers.py", line 224, in __exit__
    raise exc_value.with_traceback(exc_tb)
  File "/Users/olegkatrichuk/PycharmProjects/PythonAI/.venv/lib/python3.13/site-packages/sqlalchemy/pool/base.py", line 897, in __connect
    self.dbapi_connection = connection = pool._invoke_creator(self)
                                         ~~~~~~~~~~~~~~~~~~~~^^^^^^
  File "/Users/olegkatrichuk/PycharmProjects/PythonAI/.venv/lib/python3.13/site-packages/sqlalchemy/engine/create.py", line 646, in connect
    return dialect.connect(*cargs, **cparams)
           ~~~~~~~~~~~~~~~^^^^^^^^^^^^^^^^^^^
  File "/Users/olegkatrichuk/PycharmProjects/PythonAI/.venv/lib/python3.13/site-packages/sqlalchemy/engine/default.py", line 625, in connect
    return self.loaded_dbapi.connect(*cargs, **cparams)  # type: ignore[no-any-return]  # NOQA: E501
           ~~~~~~~~~~~~~~~~~~~~~~~~~^^^^^^^^^^^^^^^^^^^
  File "/Users/olegkatrichuk/PycharmProjects/PythonAI/.venv/lib/python3.13/site-packages/psycopg2/__init__.py", line 122, in connect
    conn = _connect(dsn, connection_factory=connection_factory, **kwasync)
sqlalchemy.exc.OperationalError: (psycopg2.OperationalError) connection to server at "localhost" (::1), port 5432 failed: Connection refused
	Is the server running on that host and accepting TCP/IP connections?
connection to server at "localhost" (127.0.0.1), port 5432 failed: Connection refused
	Is the server running on that host and accepting TCP/IP connections?

(Background on this error at: https://sqlalche.me/e/20/e3q8)
2025-07-14 11:21:39,332 - app.cache - INFO - Redis отключен
2025-07-14 11:21:41,844 - app.cache - INFO - ✅ Redis подключен успешно
2025-07-14 11:22:10,810 - app.cache - INFO - Redis отключен
2025-07-14 11:27:44,844 - app.cache - INFO - ✅ Redis подключен успешно
2025-07-14 11:37:22,074 - app.cache - INFO - ✅ Redis подключен успешно
2025-07-14 11:37:59,395 - app - INFO - User lion@gmail.com logged in successfully | user_id=26
2025-07-14 11:39:02,305 - app.cache - INFO - Redis отключен
2025-07-14 11:43:39,878 - app.cache - INFO - ✅ Redis подключен успешно
2025-07-14 11:44:20,782 - app.cache - INFO - Redis отключен
